/*
 * This example demonstrates nested `try` blocks to handle specific exceptions differently.
 * The outer `try` block handles general exceptions, while the inner `try` block
 * specifically handles the [io.file.load] invocation.
 */

// Buffer node for file's content
.file-content

try
   try
      io.file.load:x:@.file-path
      set-value:x:@.file-content
         .:x:@io.file.load
   .catch
      log.error:File not found
.catch
   log.error:An unexpected error occurred during file processing.

// Since the [.file-path] node doesn't exist, the above will throw an exception when executing [io.file.load].
