/*
 * This example illustrates the use of the `.finally` block to ensure
 * that resources are cleaned up, regardless of whether an exception occurs.
 * It opens a file, reads its content, and ensures the file is closed afterward.
 */

try
   io.file.load:x:@.file-path
.finally
   log.info:"We're done trying to read the file, byt we don't know if it was a success"

// Notice, this code will throw an exception as is, since the [.file-path] doesn't exists, implying the code will try to open a file with a null file name
// When an exception is thrown, the [.finally] block will execute, creating a log entry - But the exception will propagate out
