/*
 * This Hyperlambda snippet demonstrates nested `try` blocks with `finally`.
 * The inner `try` block throws an exception, but the `finally` block still executes.
 * Expected behavior: `.throws` should be `true`.
 */

.throws:bool:false
try
   try
      throw:foo
   .finally
      set-value:x:@.throws
         .:bool:true
.catch
